<?xml version="1.0" encoding="utf-8"?>
<robot name="phantom_touch" xmlns:xacro="http://www.ros.org/wiki/xacro">
	
  <xacro:macro name="phantom_touch" params="prefix">
    <!-- Materials -->
    <material name="metal_seamed">
      <color rgba="0.4627450980392157 0.4666666666666667 0.4509803921568628 1.0" />
    </material>
    <material name="blue">
      <color rgba="0.0 0.0 0.8 1.0" />
    </material>
    <material name="white">
      <color rgba="1.0 1.0 1.0 1.0" />
    </material>
    
    <!-- Links -->
    <link name="${prefix}base" />
    <link name="${prefix}base_bottom" >
      <visual>
        <origin xyz="0 -0.02 0" />
        <geometry>
          <mesh filename="package://phantom_touch_description/meshes/base.stl" />
        </geometry>
        <material name="metal_seamed"/>
      </visual>
    </link>
    <link name="${prefix}torso" >
      <visual>
        <origin xyz="0 0 0.036" rpy="-1.5707 0 0"/>
        <geometry>
          <mesh filename="package://phantom_touch_description/meshes/torso.stl" />
        </geometry>
        <material name="blue"/>
      </visual>
    </link>
    <link name="${prefix}upper_arm" >
      <visual>
        <origin xyz="0.0075 0 0" rpy="0 0 0"/>
        <geometry>
          <mesh filename="package://phantom_touch_description/meshes/upper_arm.stl" />
        </geometry>
        <material name="metal_seamed" />
      </visual>
    </link>
    <link name="${prefix}lower_arm" >
      <visual>
        <origin xyz="0 0 0" rpy="1.5707 0 0"/>
        <geometry>
          <mesh filename="package://phantom_touch_description/meshes/lower_arm.stl" />
        </geometry>
        <material name="metal_seamed" />
      </visual>
    </link>
    <link name="${prefix}wrist" >
      <visual>
        <origin xyz="0 0 0" rpy="3.14159 0 0"/>
        <geometry>
          <mesh filename="package://phantom_touch_description/meshes/wrist.stl" />
        </geometry>
        <material name="metal_seamed" />
      </visual>
    </link>
    <link name="${prefix}tip" >
      <visual>
        <origin xyz="0 0 0" rpy="-1.5707 0 0"/>
        <geometry>
          <mesh filename="package://phantom_touch_description/meshes/tip.stl" />
        </geometry>
        <material name="metal_seamed" />
      </visual>
    </link>
    <link name="${prefix}stylus" >
      <visual>
        <origin xyz="0 -0.033 0" rpy="1.5707 1.5707 0"/>
        <geometry>
          <mesh filename="package://phantom_touch_description/meshes/pen.stl" />
        </geometry>
        <material name="blue" />
      </visual>
    </link>

    <link name="${prefix}stylus_point" >
    </link>
    
    <!-- joints -->
    <joint name="${prefix}connector_joint" type="fixed" >
      <parent link="${prefix}base" />
      <child link="${prefix}base_bottom" />
      <origin xyz="0 0 0.0" rpy="0 0 -1.5707" />
    </joint>
    <joint name="${prefix}waist" type="revolute" >
      <parent link="${prefix}base_bottom" />
      <child link="${prefix}torso" />
      <origin xyz="0 0 0.09" rpy="0 0 0" />
      <axis xyz="0 0 -1" />
      <limit lower="-0.98" upper="0.98" velocity="100" effort="5" />
    </joint>
    <joint name="${prefix}shoulder" type="revolute" >
      <parent link="${prefix}torso" />
      <child link="${prefix}upper_arm" />
      <origin xyz="-0.0075 0 0.035" rpy="0 0 0" />
      <axis xyz="1 0 0" />
      <limit lower="0" upper="1.75" velocity="100" effort="5" />
    </joint>
    <joint name="${prefix}elbow" type="revolute" >
      <parent link="${prefix}upper_arm" />
      <child link="${prefix}lower_arm" />
      <origin xyz="0.0075 .134 0" rpy="-1.5 0 0" />
      <axis xyz="1 0 0" />
      <!-- upper="1.25" -->
      <limit lower="-0.81" upper="1.25" velocity="100" effort="5" /> 
    </joint>
    <joint name="${prefix}yaw" type="revolute" >
      <parent link="${prefix}lower_arm" />
      <child link="${prefix}wrist" />
      <origin xyz="0 0.08 0" />
      <axis xyz="0 -1 0" />
      <limit lower="3.92" upper="8.83" velocity="100" effort="5" />
    </joint>
    <joint name="${prefix}pitch" type="revolute" >
      <parent link="${prefix}wrist" />
      <child link="${prefix}tip" />
      <origin xyz="0 0.0525 0" rpy="1.5 0 0" />
      <axis xyz="1 0 0" />
      <limit lower="-0.5" upper="1.75" velocity="100" effort="5" />
    </joint>
    <joint name="${prefix}roll" type="revolute" >
      <parent link="${prefix}tip" />
      <child link="${prefix}stylus" />
      <origin xyz="0 -0.023 0" rpy="-3.14159 3.14159 0" />
      <axis xyz="0 1 0" />
      <limit lower="-2.58" upper="2.58" velocity="100" effort="5" />
    </joint>

    <joint name="${prefix}stylus_point_joint" type="fixed" >
      <parent link="${prefix}stylus" />
      <child link="${prefix}stylus_point" />
      <origin xyz="0 0.0 0" rpy="1.5707 3.14159 0" />
    </joint>

  </xacro:macro>
</robot>

